Workbook

Sheet SaMip 3.0_old currencies
A1: Country | B1: Country.nr | C1: Year | D1: SAsi | E1: SAlp | F1: SAfa | G1: SAsiy | H1: SAlpy | I1: SAfay | J1: SAavey | K1: CSUPPlp | L1: CSUPPfa | M1: HSUPPsi | N1: HSUPPlp | O1: HSUPPfa | P1: TCREDsi | Q1: TCREDlp | R1: TCREDfa | S1: OTHsi | T1: OTHlp | U1: OTHfa | V1: CSUPPlpy | W1: CSUPPfay | X1: HSUPPsiy | Y1: HSUPPlpy | Z1: HSUPPfay | AA1: TCREDsiy | AB1: TCREDlpy | AC1: TCREDfay | AD1: OTHsiy | AE1: OTHlpy | AF1: OTHfay | AG1: MIPsi | AH1: MIPlp | AI1: MIPfa | AJ1: MIPsiy | AK1: MIPlpy | AL1: MIPfay | AM1: MIPavey | AN1: FAlp | AO1: FAfa | AP1: FAlpy | AQ1: FAfay | AR1: FAavey
A2: AUS | B2: 36 | C2: 1990 | D2: 540.58333 | E2: 611.86667 | F2: 965.03333 | G2: 6487 | H2: 7342.4 | I2: 11580.4 | J2: 8469.9333 | K2: 338 | L2: 338 | M2: 108.33333 | N2: 130 | O2: 130 | P2: 0 | Q2: 0 | R2: 0 | S2: 0 | T2: 0 | U2: 0 | V2: 4056 | W2: 4056 | X2: 1300 | Y2: 1560 | Z2: 1560 | AA2: 0 | AB2: 0 | AC2: 0 | AD2: 0 | AE2: 0 | AF2: 0 | AG2: 648.91667 | AH2: 1079.8667 | AI2: 1433.0333 | AJ2: 7787 | AK2: 12958.4 | AL2: 17196.4 | AM2: 12647.267 | AN2: 949.86667 | AO2: 1303.0333 | AP2: 11398.4 | AQ2: 15636.4 | AR2: 13517.4
A3: AUS | B3: 36 | C3: 1991 | D3: 581.96667 | E3: 632.01667 | F3: 1053.8667 | G3: 6983.6 | H3: 7584.2 | I3: 12646.4 | J3: 9071.4 | K3: 369 | L3: 369 | M3: 134.33333 | N3: 156.86667 | O3: 156.86667 | P3: 0 | Q3: 0 | R3: 0 | S3: 0 | T3: 0 | U3: 0 | V3: 4428 | W3: 4428 | X3: 1612 | Y3: 1882.4 | Z3: 1882.4 | AA3: 0 | AB3: 0 | AC3: 0 | AD3: 0 | AE3: 0 | AF3: 0 | AG3: 716.3 | AH3: 1157.8833 | AI3: 1579.7333 | AJ3: 8595.6 | AK3: 13894.6 | AL3: 18956.8 | AM3: 13815.667 | AN3: 1001.0167 | AO3: 1422.8667 | AP3: 12012.2 | AQ3: 17074.4 | AR3: 14543.3
A4: AUS | B4: 36 | C4: 1992 | D4: 601.68333 | E4: 653.46667 | F4: 1089.8333 | G4: 7220.2 | H4: 7841.6 | I4: 13078 | J4: 9379.9333 | K4: 381.55 | L4: 381.55 | M4: 136.28333 | N4: 159.25 | O4: 159.25 | P4: 0 | Q4: 0 | R4: 0 | S4: 0 | T4: 0 | U4: 0 | V4: 4578.6 | W4: 4578.6 | X4: 1635.4 | Y4: 1911 | Z4: 1911 | AA4: 0 | AB4: 0 | AC4: 0 | AD4: 0 | AE4: 0 | AF4: 0 | AG4: 737.96667 | AH4: 1194.2667 | AI4: 1630.6333 | AJ4: 8855.6 | AK4: 14331.2 | AL4: 19567.6 | AM4: 14251.467 | AN4: 1035.0167 | AO4: 1471.3833 | AP4: 12420.2 | AQ4: 17656.6 | AR4: 15038.4
A5: AUS | B5: 36 | C5: 1993 | D5: 610.78333 | E5: 676.22 | F5: 1106.3 | G5: 7329.4 | H5: 8114.64 | I5: 13275.6 | J5: 9573.2133 | K5: 414.05 | L5: 414.05 | M5: 145.6 | N5: 170.08333 | O5: 170.08333 | P5: 0 | Q5: 0 | R5: 0 | S5: 0 | T5: 0 | U5: 0 | V5: 4968.6 | W5: 4968.6 | X5: 1747.2 | Y5: 2041 | Z5: 2041 | AA5: 0 | AB5: 0 | AC5: 0 | AD5: 0 | AE5: 0 | AF5: 0 | AG5: 756.38333 | AH5: 1260.3533 | AI5: 1690.4333 | AJ5: 9076.6 | AK5: 15124.24 | AL5: 20285.2 | AM5: 14828.68 | AN5: 1090.27 | AO5: 1520.35 | AP5: 13083.24 | AQ5: 18244.2 | AR5: 15663.72
A6: AUS | B6: 36 | C6: 1994 | D6: 620.53333 | E6: 689.22 | F6: 1142.7 | G6: 7446.4 | H6: 8270.64 | I6: 13712.4 | J6: 9809.8133 | K6: 427.7 | L6: 427.7 | M6: 148.2 | N6: 173.16 | O6: 173.16 | P6: 0 | Q6: 0 | R6: 0 | S6: 0 | T6: 0 | U6: 0 | V6: 5132.4 | W6: 5132.4 | X6: 1778.4 | Y6: 2077.92 | Z6: 2077.92 | AA6: 0 | AB6: 0 | AC6: 0 | AD6: 0 | AE6: 0 | AF6: 0 | AG6: 768.73333 | AH6: 1290.08 | AI6: 1743.56 | AJ6: 9224.8 | AK6: 15480.96 | AL6: 20922.72 | AM6: 15209.493 | AN6: 1116.92 | AO6: 1570.4 | AP6: 13403.04 | AQ6: 18844.8 | AR6: 16123.92
A7: AUS | B7: 36 | C7: 1995 | D7: 644.15 | E7: 739.1 | F7: 1161.3333 | G7: 7729.8 | H7: 8869.2 | I7: 13936 | J7: 10178.333 | K7: 443.51 | L7: 443.51 | M7: 152.1 | N7: 177.66667 | O7: 177.66667 | P7: 0 | Q7: 0 | R7: 0 | S7: 0 | T7: 0 | U7: 0 | V7: 5322.12 | W7: 5322.12 | X7: 1825.2 | Y7: 2132 | Z7: 2132 | AA7: 0 | AB7: 0 | AC7: 0 | AD7: 0 | AE7: 0 | AF7: 0 | AG7: 796.25 | AH7: 1360.2767 | AI7: 1782.51 | AJ7: 9555 | AK7: 16323.32 | AL7: 21390.12 | AM7: 15756.147 | AN7: 1182.61 | AO7: 1604.8433 | AP7: 14191.32 | AQ7: 19258.12 | AR7: 16724.72
A8: AUS | B8: 36 | C8: 1996 | D8: 672.75 | E8: 798.45 | F8: 1213.3333 | G8: 8073 | H8: 9581.4 | I8: 14560 | J8: 10738.133 | K8: 464.45 | L8: 464.45 | M8: 159.9 | N8: 175.37 | O8: 175.37 | P8: 0 | Q8: 0 | R8: 0 | S8: 0 | T8: 0 | U8: 0 | V8: 5573.4 | W8: 5573.4 | X8: 1918.8 | Y8: 2104.44 | Z8: 2104.44 | AA8: 0 | AB8: 0 | AC8: 0 | AD8: 0 | AE8: 0 | AF8: 0 | AG8: 832.65 | AH8: 1438.27 | AI8: 1853.1533 | AJ8: 9991.8 | AK8: 17259.24 | AL8: 22237.84 | AM8: 16496.293 | AN8: 1262.9 | AO8: 1677.7833 | AP8: 15154.8 | AQ8: 20133.4 | AR8: 17644.1
A9: AUS | B9: 36 | C9: 1997 | D9: 693.76667 | E9: 765.3 | F9: 1248 | G9: 8325.2 | H9: 9183.6 | I9: 14976 | J9: 10828.267 | K9: 613.4 | L9: 613.4 | M9: 162.06667 | N9: 189.36667 | O9: 189.36667 | P9: 0 | Q9: 0 | R9: 0 | S9: 0 | T9: 0 | U9: 0 | V9: 7360.8 | W9: 7360.8 | X9: 1944.8 | Y9: 2272.4 | Z9: 2272.4 | AA9: 0 | AB9: 0 | AC9: 0 | AD9: 0 | AE9: 0 | AF9: 0 | AG9: 855.83333 | AH9: 1568.0667 | AI9: 2050.7667 | AJ9: 10270 | AK9: 18816.8 | AL9: 24609.2 | AM9: 17898.667 | AN9: 1378.7 | AO9: 1861.4 | AP9: 16544.4 | AQ9: 22336.8 | AR9: 19440.6
A10: AUS | B10: 36 | C10: 1998 | D10: 696.58333 | E10: 798.45 | F10: 1256.6667 | G10: 8359 | H10: 9581.4 | I10: 15080 | J10: 11006.8 | K10: 621.5 | L10: 621.5 | M10: 162.93333 | N10: 190.40667 | O10: 190.40667 | P10: 0 | Q10: 0 | R10: 0 | S10: 0 | T10: 0 | U10: 0 | V10: 7458 | W10: 7458 | X10: 1955.2 | Y10: 2284.88 | Z10: 2284.88 | AA10: 0 | AB10: 0 | AC10: 0 | AD10: 0 | AE10: 0 | AF10: 0 | AG10: 859.51667 | AH10: 1610.3567 | AI10: 2068.5733 | AJ10: 10314.2 | AK10: 19324.28 | AL10: 24822.88 | AM10: 18153.787 | AN10: 1419.95 | AO10: 1878.1667 | AP10: 17039.4 | AQ10: 22538 | AR10: 19788.7
A11: AUS | B11: 36 | C11: 1999 | D11: 700.7 | E11: 805.8 | F11: 1264.4667 | G11: 8408.4 | H11: 9669.6 | I11: 15173.6 | J11: 11083.867 | K11: 629.6 | L11: 629.6 | M11: 164.23333 | N11: 191.92333 | O11: 191.92333 | P11: 0 | Q11: 0 | R11: 0 | S11: 0 | T11: 0 | U11: 0 | V11: 7555.2 | W11: 7555.2 | X11: 1970.8 | Y11: 2303.08 | Z11: 2303.08 | AA11: 0 | AB11: 0 | AC11: 0 | AD11: 0 | AE11: 0 | AF11: 0 | AG11: 864.93333 | AH11: 1627.3233 | AI11: 2085.99 | AJ11: 10379.2 | AK11: 19527.88 | AL11: 25031.88 | AM11: 18312.987 | AN11: 1435.4 | AO11: 1894.0667 | AP11: 17224.8 | AQ11: 22728.8 | AR11: 19976.8
A12: AUS | B12: 36 | C12: 2000 | D12: 707.85 | E12: 798.45 | F12: 1277.0333 | G12: 8494.2 | H12: 9581.4 | I12: 15324.4 | J12: 11133.333 | K12: 783.35 | L12: 783.35 | M12: 184.63 | N12: 215.65 | O12: 215.65 | P12: 0 | Q12: 0 | R12: 0 | S12: 0 | T12: 0 | U12: 0 | V12: 9400.2 | W12: 9400.2 | X12: 2215.56 | Y12: 2587.8 | Z12: 2587.8 | AA12: 0 | AB12: 0 | AC12: 0 | AD12: 0 | AE12: 0 | AF12: 0 | AG12: 892.48 | AH12: 1797.45 | AI12: 2276.0333 | AJ12: 10709.76 | AK12: 21569.4 | AL12: 27312.4 | AM12: 19863.853 | AN12: 1581.8 | AO12: 2060.3833 | AP12: 18981.6 | AQ12: 24724.6 | AR12: 21853.1
A13: AUS | B13: 36 | C13: 2001 | D13: 760.06667 | E13: 883.6 | F13: 1371.0667 | G13: 9120.8 | H13: 10603.2 | I13: 16452.8 | J13: 12058.933 | K13: 937.1 | L13: 937.1 | M13: 190.66667 | N13: 222.69 | O13: 222.69 | P13: 0 | Q13: 0 | R13: 0 | S13: 0 | T13: 0 | U13: 0 | V13: 11245.2 | W13: 11245.2 | X13: 2288 | Y13: 2672.28 | Z13: 2672.28 | AA13: 0 | AB13: 0 | AC13: 0 | AD13: 0 | AE13: 0 | AF13: 0 | AG13: 950.73333 | AH13: 2043.39 | AI13: 2530.8567 | AJ13: 11408.8 | AK13: 24520.68 | AL13: 30370.28 | AM13: 22099.92 | AN13: 1820.7 | AO13: 2308.1667 | AP13: 21848.4 | AQ13: 27698 | AR13: 24773.2
... A34: AUS | B34: 36 | C34: 2022 | D34: 1382.9833 | E34: 1556.9667 | F34: 2518.5333 | G34: 16595.8 | H34: 18683.6 | I34: 30222.4 | J34: 21833.933 | K34: 1726.792 | L34: 1214.9167 | M34: 309.4 | N34: 365 | O34: 365 | P34: 0 | Q34: 0 | R34: 0 | S34: 0 | T34: 0 | U34: 0 | V34: 20721.504 | W34: 14579 | X34: 3712.8 | Y34: 4380 | Z34: 4380 | AA34: 0 | AB34: 0 | AC34: 0 | AD34: 0 | AE34: 0 | AF34: 0 | AG34: 1692.3833 | AH34: 3648.7587 | AI34: 4098.45 | AJ34: 20308.6 | AK34: 43785.104 | AL34: 49181.4 | AM34: 37758.368 | AN34: 3283.7587 | AO34: 3733.45 | AP34: 39405.104 | AQ34: 44801.4 | AR34: 42103.252
A35: AUS | B35: 36 | C35: 2023
A36: AUT | B36: 40 | C36: 1990 | D36: 3791 | E36: 6074 | F36: 7974 | G36: 45492 | H36: 72888 | I36: 95688 | J36: 71356 | K36: 2850 | L36: 2850 | M36: 2384 | N36: 2384 | O36: 2384 | P36: 0 | Q36: 0 | R36: 0 | S36: 0 | T36: 0 | U36: 0 | V36: 34200 | W36: 34200 | X36: 28608 | Y36: 28608 | Z36: 28608 | AA36: 0 | AB36: 0 | AC36: 0 | AD36: 0 | AE36: 0 | AF36: 0 | AG36: 6175 | AH36: 11308 | AI36: 13208 | AJ36: 74100 | AK36: 135696 | AL36: 158496 | AM36: 122764 | AN36: 8924 | AO36: 10824 | AP36: 107088 | AQ36: 129888 | AR36: 118488
A37: AUT | B37: 40 | C37: 1991 | D37: 3791 | E37: 6074 | F37: 7974 | G37: 45492 | H37: 72888 | I37: 95688 | J37: 71356 | K37: 2850 | L37: 2850 | M37: 2384 | N37: 2384 | O37: 2384 | P37: 0 | Q37: 0 | R37: 0 | S37: 0 | T37: 0 | U37: 0 | V37: 34200 | W37: 34200 | X37: 28608 | Y37: 28608 | Z37: 28608 | AA37: 0 | AB37: 0 | AC37: 0 | AD37: 0 | AE37: 0 | AF37: 0 | AG37: 6175 | AH37: 11308 | AI37: 13208 | AJ37: 74100 | AK37: 135696 | AL37: 158496 | AM37: 122764 | AN37: 8924 | AO37: 10824 | AP37: 107088 | AQ37: 129888 | AR37: 118488
A38: AUT | B38: 40 | C38: 1992 | D38: 4350 | E38: 6870 | F38: 9050 | G38: 52200 | H38: 82440 | I38: 108600 | J38: 81080 | K38: 2850 | L38: 2850 | M38: 2689 | N38: 2689 | O38: 2689 | P38: 0 | Q38: 0 | R38: 0 | S38: 0 | T38: 0 | U38: 0 | V38: 34200 | W38: 34200 | X38: 32268 | Y38: 32268 | Z38: 32268 | AA38: 0 | AB38: 0 | AC38: 0 | AD38: 0 | AE38: 0 | AF38: 0 | AG38: 7039 | AH38: 12409 | AI38: 14589 | AJ38: 84468 | AK38: 148908 | AL38: 175068 | AM38: 136148 | AN38: 9720 | AO38: 11900 | AP38: 116640 | AQ38: 142800 | AR38: 129720
A39: AUT | B39: 40 | C39: 1993 | D39: 4530 | E39: 7140 | F39: 9410 | G39: 54360 | H39: 85680 | I39: 112920 | J39: 84320 | K39: 4141.67 | L39: 4141.67 | M39: 2778 | N39: 2778 | O39: 2778 | P39: 0 | Q39: 0 | R39: 0 | S39: 0 | T39: 0 | U39: 0 | V39: 49700.04 | W39: 49700.04 | X39: 33336 | Y39: 33336 | Z39: 33336 | AA39: 0 | AB39: 0 | AC39: 0 | AD39: 0 | AE39: 0 | AF39: 0 | AG39: 7308 | AH39: 14059.67 | AI39: 16329.67 | AJ39: 87696 | AK39: 168716.04 | AL39: 195956.04 | AM39: 150789.36 | AN39: 11281.67 | AO39: 13551.67 | AP39: 135380.04 | AQ39: 162620.04 | AR39: 149000.04
A40: AUT | B40: 40 | C40: 1994 | D40: 4640 | E40: 7424 | F40: 9632 | G40: 55680 | H40: 89088 | I40: 115584 | J40: 86784 | K40: 4141.67 | L40: 4141.67 | M40: 2867 | N40: 2867 | O40: 2867 | P40: 0 | Q40: 0 | R40: 0 | S40: 0 | T40: 0 | U40: 0 | V40: 49700.04 | W40: 49700.04 | X40: 34404 | Y40: 34404 | Z40: 34404 | AA40: 0 | AB40: 0 | AC40: 0 | AD40: 0 | AE40: 0 | AF40: 0 | AG40: 7507 | AH40: 14432.67 | AI40: 16640.67 | AJ40: 90084 | AK40: 173192.04 | AL40: 199688.04 | AM40: 154321.36 | AN40: 11565.67 | AO40: 13773.67 | AP40: 138788.04 | AQ40: 165284.04 | AR40: 152036.04
A41: AUT | B41: 40 | C41: 1995 | D41: 4770 | E41: 7632 | F41: 9902 | G41: 57240 | H41: 91584 | I41: 118824 | J41: 89216 | K41: 4141.67 | L41: 4141.67 | M41: 2948 | N41: 2948 | O41: 2948 | P41: 0 | Q41: 0 | R41: 0 | S41: 0 | T41: 0 | U41: 0 | V41: 49700.04 | W41: 49700.04 | X41: 35376 | Y41: 35376 | Z41: 35376 | AA41: 0 | AB41: 0 | AC41: 0 | AD41: 0 | AE41: 0 | AF41: 0 | AG41: 7718 | AH41: 14721.67 | AI41: 16991.67 | AJ41: 92616 | AK41: 176660.04 | AL41: 203900.04 | AM41: 157725.36 | AN41: 11773.67 | AO41: 14043.67 | AP41: 141284.04 | AQ41: 168524.04 | AR41: 154904.04
A42: AUT | B42: 40 | C42: 1996 | D42: 4880 | E42: 7808 | F42: 10130 | G42: 58560 | H42: 93696 | I42: 121560 | J42: 91272 | K42: 4141.67 | L42: 4141.67 | M42: 3100 | N42: 3132.67 | O42: 3132.67 | P42: 0 | Q42: 0 | R42: 0 | S42: 0 | T42: 0 | U42: 0 | V42: 49700.04 | W42: 49700.04 | X42: 37200 | Y42: 37592.04 | Z42: 37592.04 | AA42: 0 | AB42: 0 | AC42: 0 | AD42: 0 | AE42: 0 | AF42: 0 | AG42: 7980 | AH42: 15082.34 | AI42: 17404.34 | AJ42: 95760 | AK42: 180988.08 | AL42: 208852.08 | AM42: 161866.72 | AN42: 11949.67 | AO42: 14271.67 | AP42: 143396.04 | AQ42: 171260.04 | AR42: 157328.04
A43: AUT | B43: 40 | C43: 1997 | D43: 4880 | E43: 7808 | F43: 10708 | G43: 58560 | H43: 93696 | I43: 128496 | J43: 93584 | K43: 4141.67 | L43: 4141.67 | M43: 3252 | N43: 3317.33 | O43: 3317.33 | P43: 0 | Q43: 0 | R43: 0 | S43: 0 | T43: 0 | U43: 0 | V43: 49700.04 | W43: 49700.04 | X43: 39024 | Y43: 39807.96 | Z43: 39807.96 | AA43: 0 | AB43: 0 | AC43: 0 | AD43: 0 | AE43: 0 | AF43: 0 | AG43: 8132 | AH43: 15267 | AI43: 18167 | AJ43: 97584 | AK43: 183204 | AL43: 218004 | AM43: 166264 | AN43: 11949.67 | AO43: 14849.67 | AP43: 143396.04 | AQ43: 178196.04 | AR43: 160796.04
A44: AUT | B44: 40 | C44: 1998 | D44: 4929 | E44: 7886 | F44: 10563 | G44: 59148 | H44: 94632 | I44: 126756 | J44: 93512 | K44: 4141.67 | L44: 4141.67 | M44: 3404 | N44: 3502 | O44: 3502 | P44: 0 | Q44: 0 | R44: 0 | S44: 0 | T44: 0 | U44: 0 | V44: 49700.04 | W44: 49700.04 | X44: 40848 | Y44: 42024 | Z44: 42024 | AA44: 0 | AB44: 0 | AC44: 0 | AD44: 0 | AE44: 0 | AF44: 0 | AG44: 8333 | AH44: 15529.67 | AI44: 18206.67 | AJ44: 99996 | AK44: 186356.04 | AL44: 218480.04 | AM44: 168277.36 | AN44: 12027.67 | AO44: 14704.67 | AP44: 144332.04 | AQ44: 176456.04 | AR44: 160394.04
A45: AUT | B45: 40 | C45: 1999 | D45: 5019 | E45: 8029 | F45: 10417 | G45: 60228 | H45: 96348 | I45: 125004 | J45: 93860 | K45: 4641.67 | L45: 4641.67 | M45: 3556 | N45: 3686.67 | O45: 3686.67 | P45: 0 | Q45: 0 | R45: 0 | S45: 0 | T45: 0 | U45: 0 | V45: 55700.04 | W45: 55700.04 | X45: 42672 | Y45: 44240.04 | Z45: 44240.04 | AA45: 0 | AB45: 0 | AC45: 0 | AD45: 0 | AE45: 0 | AF45: 0 | AG45: 8575 | AH45: 16357.34 | AI45: 18745.34 | AJ45: 102900 | AK45: 196288.08 | AL45: 224944.08 | AM45: 174710.72 | AN45: 12670.67 | AO45: 15058.67 | AP45: 152048.04 | AQ45: 180704.04 | AR45: 166376.04
A46: AUT | B46: 40 | C46: 2000 | D46: 5142 | E46: 8190 | F46: 10625 | G46: 61704 | H46: 98280 | I46: 127500 | J46: 95828 | K46: 4725 | L46: 4725 | M46: 3708 | N46: 3871.33 | O46: 3871.33 | P46: 0 | Q46: 0 | R46: 0 | S46: 0 | T46: 0 | U46: 0 | V46: 56700 | W46: 56700 | X46: 44496 | Y46: 46455.96 | Z46: 46455.96 | AA46: 0 | AB46: 0 | AC46: 0 | AD46: 0 | AE46: 0 | AF46: 0 | AG46: 8850 | AH46: 16786.33 | AI46: 19221.33 | AJ46: 106200 | AK46: 201435.96 | AL46: 230655.96 | AM46: 179430.64 | AN46: 12915 | AO46: 15350 | AP46: 154980 | AQ46: 184200 | AR46: 169590
A47: AUT | B47: 40 | C47: 2001 | D47: 5220 | E47: 8350 | F47: 10833 | G47: 62640 | H47: 100200 | I47: 129996 | J47: 97612 | K47: 4725 | L47: 4725 | M47: 3860 | N47: 4056 | O47: 4056 | P47: 0 | Q47: 416.66667 | R47: 416.66667 | S47: 0 | T47: 0 | U47: 0 | V47: 56700 | W47: 56700 | X47: 46320 | Y47: 48672 | Z47: 48672 | AA47: 0 | AB47: 5000 | AC47: 5000 | AD47: 0 | AE47: 0 | AF47: 0 | AG47: 9080 | AH47: 17547.667 | AI47: 20030.667 | AJ47: 108960 | AK47: 210572 | AL47: 240368 | AM47: 186633.33 | AN47: 13491.667 | AO47: 15974.667 | AP47: 161900 | AQ47: 191696 | AR47: 176798
... A68: AUT | B68: 40 | C68: 2022 | D68: 10431.569 | E68: 17698.154 | F68: 22749.445 | G68: 125178.83 | H68: 212377.85 | I68: 272993.34 | J68: 203516.67 | K68: 5656.4007 | L68: 5656.4007 | M68: 5029.275 | N68: 5272.947 | O68: 5272.947 | P68: 0 | Q68: 767.13673 | R68: 767.13673 | S68: 0 | T68: 0 | U68: 0 | V68: 67876.808 | W68: 67876.808 | X68: 60351.3 | Y68: 63275.364 | Z68: 63275.364 | AA68: 0 | AB68: 9205.6407 | AC68: 9205.6407 | AD68: 0 | AE68: 0 | AF68: 0 | AG68: 15460.844 | AH68: 29394.638 | AI68: 34445.93 | AJ68: 185530.12 | AK68: 352735.66 | AL68: 413351.16 | AM68: 317205.65 | AN68: 24121.691 | AO68: 29172.983 | AP68: 289460.29 | AQ68: 350075.79 | AR68: 319768.04
A69: AUT | B69: 40 | C69: 2023
A70: BEL | B70: 56 | C70: 1990 | D70: 17303 | E70: 23070 | F70: 23070 | G70: 207636 | H70: 276840 | I70: 276840 | J70: 253772 | K70: 9547.5 | L70: 9547.5 | M70: 0 | N70: 0 | O70: 0 | P70: 0 | Q70: 0 | R70: 0 | S70: 0 | T70: 0 | U70: 0 | V70: 114570 | W70: 114570 | X70: 0 | Y70: 0 | Z70: 0 | AA70: 0 | AB70: 0 | AC70: 0 | AD70: 0 | AE70: 0 | AF70: 0 | AG70: 17303 | AH70: 32617.5 | AI70: 32617.5 | AJ70: 207636 | AK70: 391410 | AL70: 391410 | AM70: 330152 | AN70: 32617.5 | AO70: 32617.5 | AP70: 391410 | AQ70: 391410 | AR70: 391410
A71: BEL | B71: 56 | C71: 1991 | D71: 18362 | E71: 23258 | F71: 23258 | G71: 220344 | H71: 279096 | I71: 279096 | J71: 259512 | K71: 10358.25 | L71: 10358.25 | M71: 0 | N71: 0 | O71: 0 | P71: 0 | Q71: 0 | R71: 0 | S71: 0 | T71: 0 | U71: 0 | V71: 124299 | W71: 124299 | X71: 0 | Y71: 0 | Z71: 0 | AA71: 0 | AB71: 0 | AC71: 0 | AD71: 0 | AE71: 0 | AF71: 0 | AG71: 18362 | AH71: 33616.25 | AI71: 33616.25 | AJ71: 220344 | AK71: 403395 | AL71: 403395 | AM71: 342378 | AN71: 33616.25 | AO71: 33616.25 | AP71: 403395 | AQ71: 403395 | AR71: 403395
A72: BEL | B72: 56 | C72: 1992 | D72: 18729 | E72: 24971 | F72: 24971 | G72: 224748 | H72: 299652 | I72: 299652 | J72: 274684 | K72: 11169 | L72: 11169 | M72: 0 | N72: 0 | O72: 0 | P72: 0 | Q72: 0 | R72: 0 | S72: 0 | T72: 0 | U72: 0 | V72: 134028 | W72: 134028 | X72: 0 | Y72: 0 | Z72: 0 | AA72: 0 | AB72: 0 | AC72: 0 | AD72: 0 | AE72: 0 | AF72: 0 | AG72: 18729 | AH72: 36140 | AI72: 36140 | AJ72: 224748 | AK72: 433680 | AL72: 433680 | AM72: 364036 | AN72: 36140 | AO72: 36140 | AP72: 433680 | AQ72: 433680 | AR72: 433680
A73: BEL | B73: 56 | C73: 1993 | D73: 19485 | E73: 25980 | F73: 25980 | G73: 233820 | H73: 311760 | I73: 311760 | J73: 285780 | K73: 11416 | L73: 11416 | M73: 0 | N73: 0 | O73: 0 | P73: 0 | Q73: 0 | R73: 0 | S73: 0 | T73: 0 | U73: 0 | V73: 136992 | W73: 136992 | X73: 0 | Y73: 0 | Z73: 0 | AA73: 0 | AB73: 0 | AC73: 0 | AD73: 0 | AE73: 0 | AF73: 0 | AG73: 19485 | AH73: 37396 | AI73: 37396 | AJ73: 233820 | AK73: 448752 | AL73: 448752 | AM73: 377108 | AN73: 37396 | AO73: 37396 | AP73: 448752 | AQ73: 448752 | AR73: 448752
A74: BEL | B74: 56 | C74: 1994 | D74: 19709 | E74: 26279 | F74: 26279 | G74: 236508 | H74: 315348 | I74: 315348 | J74: 289068 | K74: 11663 | L74: 11663 | M74: 0 | N74: 0 | O74: 0 | P74: 0 | Q74: 0 | R74: 0 | S74: 0 | T74: 0 | U74: 0 | V74: 139956 | W74: 139956 | X74: 0 | Y74: 0 | Z74: 0 | AA74: 0 | AB74: 0 | AC74: 0 | AD74: 0 | AE74: 0 | AF74: 0 | AG74: 19709 | AH74: 37942 | AI74: 37942 | AJ74: 236508 | AK74: 455304 | AL74: 455304 | AM74: 382372 | AN74: 37942 | AO74: 37942 | AP74: 455304 | AQ74: 455304 | AR74: 455304
A75: BEL | B75: 56 | C75: 1995 | D75: 20103 | E75: 26805 | F75: 26805 | G75: 241236 | H75: 321660 | I75: 321660 | J75: 294852 | K75: 11910 | L75: 11910 | M75: 0 | N75: 0 | O75: 0 | P75: 0 | Q75: 0 | R75: 0 | S75: 0 | T75: 0 | U75: 0 | V75: 142920 | W75: 142920 | X75: 0 | Y75: 0 | Z75: 0 | AA75: 0 | AB75: 0 | AC75: 0 | AD75: 0 | AE75: 0 | AF75: 0 | AG75: 20103 | AH75: 38715 | AI75: 38715 | AJ75: 241236 | AK75: 464580 | AL75: 464580 | AM75: 390132 | AN75: 38715 | AO75: 38715 | AP75: 464580 | AQ75: 464580 | AR75: 464580
A76: BEL | B76: 56 | C76: 1996 | D76: 20505 | E76: 27341 | F76: 27341 | G76: 246060 | H76: 328092 | I76: 328092 | J76: 300748 | K76: 12150 | L76: 12150 | M76: 0 | N76: 0 | O76: 0 | P76: 0 | Q76: 0 | R76: 0 | S76: 0 | T76: 0 | U76: 0 | V76: 145800 | W76: 145800 | X76: 0 | Y76: 0 | Z76: 0 | AA76: 0 | AB76: 0 | AC76: 0 | AD76: 0 | AE76: 0 | AF76: 0 | AG76: 20505 | AH76: 39491 | AI76: 39491 | AJ76: 246060 | AK76: 473892 | AL76: 473892 | AM76: 397948 | AN76: 39491 | AO76: 39491 | AP76: 473892 | AQ76: 473892 | AR76: 473892
A77: BEL | B77: 56 | C77: 1997 | D77: 20505 | E77: 27341 | F77: 27341 | G77: 246060 | H77: 328092 | I77: 328092 | J77: 300748 | K77: 12390 | L77: 12390 | M77: 0 | N77: 0 | O77: 0 | P77: 0 | Q77: 0 | R77: 0 | S77: 0 | T77: 0 | U77: 0 | V77: 148680 | W77: 148680 | X77: 0 | Y77: 0 | Z77: 0 | AA77: 0 | AB77: 0 | AC77: 0 | AD77: 0 | AE77: 0 | AF77: 0 | AG77: 20505 | AH77: 39731 | AI77: 39731 | AJ77: 246060 | AK77: 476772 | AL77: 476772 | AM77: 399868 | AN77: 39731 | AO77: 39731 | AP77: 476772 | AQ77: 476772 | AR77: 476772
A78: BEL | B78: 56 | C78: 1998 | D78: 20916 | E78: 27888 | F78: 27888 | G78: 250992 | H78: 334656 | I78: 334656 | J78: 306768 | K78: 12275 | L78: 12275 | M78: 0 | N78: 0 | O78: 0 | P78: 0 | Q78: 0 | R78: 0 | S78: 0 | T78: 0 | U78: 0 | V78: 147300 | W78: 147300 | X78: 0 | Y78: 0 | Z78: 0 | AA78: 0 | AB78: 0 | AC78: 0 | AD78: 0 | AE78: 0 | AF78: 0 | AG78: 20916 | AH78: 40163 | AI78: 40163 | AJ78: 250992 | AK78: 481956 | AL78: 481956 | AM78: 404968 | AN78: 40163 | AO78: 40163 | AP78: 481956 | AQ78: 481956 | AR78: 481956
A79: BEL | B79: 56 | C79: 1999 | D79: 21134 | E79: 28445 | F79: 28445 | G79: 253608 | H79: 341340 | I79: 341340 | J79: 312096 | K79: 12160 | L79: 12160 | M79: 0 | N79: 0 | O79: 0 | P79: 0 | Q79: 0 | R79: 0 | S79: 0 | T79: 0 | U79: 0 | V79: 145920 | W79: 145920 | X79: 0 | Y79: 0 | Z79: 0 | AA79: 0 | AB79: 0 | AC79: 0 | AD79: 0 | AE79: 0 | AF79: 0 | AG79: 21134 | AH79: 40605 | AI79: 40605 | AJ79: 253608 | AK79: 487260 | AL79: 487260 | AM79: 409376 | AN79: 40605 | AO79: 40605 | AP79: 487260 | AQ79: 487260 | AR79: 487260
A80: BEL | B80: 56 | C80: 2000 | D80: 21761 | E80: 29015 | F80: 29015 | G80: 261132 | H80: 348180 | I80: 348180 | J80: 319164 | K80: 12618 | L80: 12618 | M80: 0 | N80: 0 | O80: 0 | P80: 0 | Q80: 0 | R80: 0 | S80: 0 | T80: 0 | U80: 0 | V80: 151416 | W80: 151416 | X80: 0 | Y80: 0 | Z80: 0 | AA80: 0 | AB80: 0 | AC80: 0 | AD80: 0 | AE80: 0 | AF80: 0 | AG80: 21761 | AH80: 41633 | AI80: 41633 | AJ80: 261132 | AK80: 499596 | AL80: 499596 | AM80: 420108 | AN80: 41633 | AO80: 41633 | AP80: 499596 | AQ80: 499596 | AR80: 499596
...

Sheet SaMip 3.0_new currencies
A1: Country | B1: Country.nr | C1: Year | D1: SAsi | E1: SAlp | F1: SAfa | G1: SAsiy | H1: SAlpy | I1: SAfay | J1: SAavey | K1: CSUPPlp | L1: CSUPPfa | M1: HSUPPsi | N1: HSUPPlp | O1: HSUPPfa | P1: TCREDsi | Q1: TCREDlp | R1: TCREDfa | S1: OTHsi | T1: OTHlp | U1: OTHfa | V1: CSUPPlpy | W1: CSUPPfay | X1: HSUPPsiy | Y1: HSUPPlpy | Z1: HSUPPfay | AA1: TCREDsiy | AB1: TCREDlpy | AC1: TCREDfay | AD1: OTHsiy | AE1: OTHlpy | AF1: OTHfay | AG1: MIPsi | AH1: MIPlp | AI1: MIPfa | AJ1: MIPsiy | AK1: MIPlpy | AL1: MIPfay | AM1: MIPavey | AN1: FAlp | AO1: FAfa | AP1: FAlpy | AQ1: FAfay | AR1: FAavey
A2: AUS | B2: 36 | C2: 1990 | D2: 540.58333 | E2: 611.86667 | F2: 965.03333 | G2: 6487 | H2: 7342.4 | I2: 11580.4 | J2: 8469.9333 | K2: 338 | L2: 338 | M2: 108.33333 | N2: 130 | O2: 130 | P2: 0 | Q2: 0 | R2: 0 | S2: 0 | T2: 0 | U2: 0 | V2: 4056 | W2: 4056 | X2: 1300 | Y2: 1560 | Z2: 1560 | AA2: 0 | AB2: 0 | AC2: 0 | AD2: 0 | AE2: 0 | AF2: 0 | AG2: 648.91667 | AH2: 1079.8667 | AI2: 1433.0333 | AJ2: 7787 | AK2: 12958.4 | AL2: 17196.4 | AM2: 12647.267 | AN2: 949.86667 | AO2: 1303.0333 | AP2: 11398.4 | AQ2: 15636.4 | AR2: 13517.4
A3: AUS | B3: 36 | C3: 1991 | D3: 581.96667 | E3: 632.01667 | F3: 1053.8667 | G3: 6983.6 | H3: 7584.2 | I3: 12646.4 | J3: 9071.4 | K3: 369 | L3: 369 | M3: 134.33333 | N3: 156.86667 | O3: 156.86667 | P3: 0 | Q3: 0 | R3: 0 | S3: 0 | T3: 0 | U3: 0 | V3: 4428 | W3: 4428 | X3: 1612 | Y3: 1882.4 | Z3: 1882.4 | AA3: 0 | AB3: 0 | AC3: 0 | AD3: 0 | AE3: 0 | AF3: 0 | AG3: 716.3 | AH3: 1157.8833 | AI3: 1579.7333 | AJ3: 8595.6 | AK3: 13894.6 | AL3: 18956.8 | AM3: 13815.667 | AN3: 1001.0167 | AO3: 1422.8667 | AP3: 12012.2 | AQ3: 17074.4 | AR3: 14543.3
A4: AUS | B4: 36 | C4: 1992 | D4: 601.68333 | E4: 653.46667 | F4: 1089.8333 | G4: 7220.2 | H4: 7841.6 | I4: 13078 | J4: 9379.9333 | K4: 381.55 | L4: 381.55 | M4: 136.28333 | N4: 159.25 | O4: 159.25 | P4: 0 | Q4: 0 | R4: 0 | S4: 0 | T4: 0 | U4: 0 | V4: 4578.6 | W4: 4578.6 | X4: 1635.4 | Y4: 1911 | Z4: 1911 | AA4: 0 | AB4: 0 | AC4: 0 | AD4: 0 | AE4: 0 | AF4: 0 | AG4: 737.96667 | AH4: 1194.2667 | AI4: 1630.6333 | AJ4: 8855.6 | AK4: 14331.2 | AL4: 19567.6 | AM4: 14251.467 | AN4: 1035.0167 | AO4: 1471.3833 | AP4: 12420.2 | AQ4: 17656.6 | AR4: 15038.4
A5: AUS | B5: 36 | C5: 1993 | D5: 610.78333 | E5: 676.22 | F5: 1106.3 | G5: 7329.4 | H5: 8114.64 | I5: 13275.6 | J5: 9573.2133 | K5: 414.05 | L5: 414.05 | M5: 145.6 | N5: 170.08333 | O5: 170.08333 | P5: 0 | Q5: 0 | R5: 0 | S5: 0 | T5: 0 | U5: 0 | V5: 4968.6 | W5: 4968.6 | X5: 1747.2 | Y5: 2041 | Z5: 2041 | AA5: 0 | AB5: 0 | AC5: 0 | AD5: 0 | AE5: 0 | AF5: 0 | AG5: 756.38333 | AH5: 1260.3533 | AI5: 1690.4333 | AJ5: 9076.6 | AK5: 15124.24 | AL5: 20285.2 | AM5: 14828.68 | AN5: 1090.27 | AO5: 1520.35 | AP5: 13083.24 | AQ5: 18244.2 | AR5: 15663.72
A6: AUS | B6: 36 | C6: 1994 | D6: 620.53333 | E6: 689.22 | F6: 1142.7 | G6: 7446.4 | H6: 8270.64 | I6: 13712.4 | J6: 9809.8133 | K6: 427.7 | L6: 427.7 | M6: 148.2 | N6: 173.16 | O6: 173.16 | P6: 0 | Q6: 0 | R6: 0 | S6: 0 | T6: 0 | U6: 0 | V6: 5132.4 | W6: 5132.4 | X6: 1778.4 | Y6: 2077.92 | Z6: 2077.92 | AA6: 0 | AB6: 0 | AC6: 0 | AD6: 0 | AE6: 0 | AF6: 0 | AG6: 768.73333 | AH6: 1290.08 | AI6: 1743.56 | AJ6: 9224.8 | AK6: 15480.96 | AL6: 20922.72 | AM6: 15209.493 | AN6: 1116.92 | AO6: 1570.4 | AP6: 13403.04 | AQ6: 18844.8 | AR6: 16123.92
A7: AUS | B7: 36 | C7: 1995 | D7: 644.15 | E7: 739.1 | F7: 1161.3333 | G7: 7729.8 | H7: 8869.2 | I7: 13936 | J7: 10178.333 | K7: 443.51 | L7: 443.51 | M7: 152.1 | N7: 177.66667 | O7: 177.66667 | P7: 0 | Q7: 0 | R7: 0 | S7: 0 | T7: 0 | U7: 0 | V7: 5322.12 | W7: 5322.12 | X7: 1825.2 | Y7: 2132 | Z7: 2132 | AA7: 0 | AB7: 0 | AC7: 0 | AD7: 0 | AE7: 0 | AF7: 0 | AG7: 796.25 | AH7: 1360.2767 | AI7: 1782.51 | AJ7: 9555 | AK7: 16323.32 | AL7: 21390.12 | AM7: 15756.147 | AN7: 1182.61 | AO7: 1604.8433 | AP7: 14191.32 | AQ7: 19258.12 | AR7: 16724.72
A8: AUS | B8: 36 | C8: 1996 | D8: 672.75 | E8: 798.45 | F8: 1213.3333 | G8: 8073 | H8: 9581.4 | I8: 14560 | J8: 10738.133 | K8: 464.45 | L8: 464.45 | M8: 159.9 | N8: 175.37 | O8: 175.37 | P8: 0 | Q8: 0 | R8: 0 | S8: 0 | T8: 0 | U8: 0 | V8: 5573.4 | W8: 5573.4 | X8: 1918.8 | Y8: 2104.44 | Z8: 2104.44 | AA8: 0 | AB8: 0 | AC8: 0 | AD8: 0 | AE8: 0 | AF8: 0 | AG8: 832.65 | AH8: 1438.27 | AI8: 1853.1533 | AJ8: 9991.8 | AK8: 17259.24 | AL8: 22237.84 | AM8: 16496.293 | AN8: 1262.9 | AO8: 1677.7833 | AP8: 15154.8 | AQ8: 20133.4 | AR8: 17644.1
A9: AUS | B9: 36 | C9: 1997 | D9: 693.76667 | E9: 765.3 | F9: 1248 | G9: 8325.2 | H9: 9183.6 | I9: 14976 | J9: 10828.267 | K9: 613.4 | L9: 613.4 | M9: 162.06667 | N9: 189.36667 | O9: 189.36667 | P9: 0 | Q9: 0 | R9: 0 | S9: 0 | T9: 0 | U9: 0 | V9: 7360.8 | W9: 7360.8 | X9: 1944.8 | Y9: 2272.4 | Z9: 2272.4 | AA9: 0 | AB9: 0 | AC9: 0 | AD9: 0 | AE9: 0 | AF9: 0 | AG9: 855.83333 | AH9: 1568.0667 | AI9: 2050.7667 | AJ9: 10270 | AK9: 18816.8 | AL9: 24609.2 | AM9: 17898.667 | AN9: 1378.7 | AO9: 1861.4 | AP9: 16544.4 | AQ9: 22336.8 | AR9: 19440.6
A10: AUS | B10: 36 | C10: 1998 | D10: 696.58333 | E10: 798.45 | F10: 1256.6667 | G10: 8359 | H10: 9581.4 | I10: 15080 | J10: 11006.8 | K10: 621.5 | L10: 621.5 | M10: 162.93333 | N10: 190.40667 | O10: 190.40667 | P10: 0 | Q10: 0 | R10: 0 | S10: 0 | T10: 0 | U10: 0 | V10: 7458 | W10: 7458 | X10: 1955.2 | Y10: 2284.88 | Z10: 2284.88 | AA10: 0 | AB10: 0 | AC10: 0 | AD10: 0 | AE10: 0 | AF10: 0 | AG10: 859.51667 | AH10: 1610.3567 | AI10: 2068.5733 | AJ10: 10314.2 | AK10: 19324.28 | AL10: 24822.88 | AM10: 18153.787 | AN10: 1419.95 | AO10: 1878.1667 | AP10: 17039.4 | AQ10: 22538 | AR10: 19788.7
A11: AUS | B11: 36 | C11: 1999 | D11: 700.7 | E11: 805.8 | F11: 1264.4667 | G11: 8408.4 | H11: 9669.6 | I11: 15173.6 | J11: 11083.867 | K11: 629.6 | L11: 629.6 | M11: 164.23333 | N11: 191.92333 | O11: 191.92333 | P11: 0 | Q11: 0 | R11: 0 | S11: 0 | T11: 0 | U11: 0 | V11: 7555.2 | W11: 7555.2 | X11: 1970.8 | Y11: 2303.08 | Z11: 2303.08 | AA11: 0 | AB11: 0 | AC11: 0 | AD11: 0 | AE11: 0 | AF11: 0 | AG11: 864.93333 | AH11: 1627.3233 | AI11: 2085.99 | AJ11: 10379.2 | AK11: 19527.88 | AL11: 25031.88 | AM11: 18312.987 | AN11: 1435.4 | AO11: 1894.0667 | AP11: 17224.8 | AQ11: 22728.8 | AR11: 19976.8
A12: AUS | B12: 36 | C12: 2000 | D12: 707.85 | E12: 798.45 | F12: 1277.0333 | G12: 8494.2 | H12: 9581.4 | I12: 15324.4 | J12: 11133.333 | K12: 783.35 | L12: 783.35 | M12: 184.63 | N12: 215.65 | O12: 215.65 | P12: 0 | Q12: 0 | R12: 0 | S12: 0 | T12: 0 | U12: 0 | V12: 9400.2 | W12: 9400.2 | X12: 2215.56 | Y12: 2587.8 | Z12: 2587.8 | AA12: 0 | AB12: 0 | AC12: 0 | AD12: 0 | AE12: 0 | AF12: 0 | AG12: 892.48 | AH12: 1797.45 | AI12: 2276.0333 | AJ12: 10709.76 | AK12: 21569.4 | AL12: 27312.4 | AM12: 19863.853 | AN12: 1581.8 | AO12: 2060.3833 | AP12: 18981.6 | AQ12: 24724.6 | AR12: 21853.1
A13: AUS | B13: 36 | C13: 2001 | D13: 760.06667 | E13: 883.6 | F13: 1371.0667 | G13: 9120.8 | H13: 10603.2 | I13: 16452.8 | J13: 12058.933 | K13: 937.1 | L13: 937.1 | M13: 190.66667 | N13: 222.69 | O13: 222.69 | P13: 0 | Q13: 0 | R13: 0 | S13: 0 | T13: 0 | U13: 0 | V13: 11245.2 | W13: 11245.2 | X13: 2288 | Y13: 2672.28 | Z13: 2672.28 | AA13: 0 | AB13: 0 | AC13: 0 | AD13: 0 | AE13: 0 | AF13: 0 | AG13: 950.73333 | AH13: 2043.39 | AI13: 2530.8567 | AJ13: 11408.8 | AK13: 24520.68 | AL13: 30370.28 | AM13: 22099.92 | AN13: 1820.7 | AO13: 2308.1667 | AP13: 21848.4 | AQ13: 27698 | AR13: 24773.2
... A34: AUS | B34: 36 | C34: 2022 | D34: 1382.9833 | E34: 1556.9667 | F34: 2518.5333 | G34: 16595.8 | H34: 18683.6 | I34: 30222.4 | J34: 21833.933 | K34: 1726.792 | L34: 1214.9167 | M34: 309.4 | N34: 365 | O34: 365 | P34: 0 | Q34: 0 | R34: 0 | S34: 0 | T34: 0 | U34: 0 | V34: 20721.504 | W34: 14579 | X34: 3712.8 | Y34: 4380 | Z34: 4380 | AA34: 0 | AB34: 0 | AC34: 0 | AD34: 0 | AE34: 0 | AF34: 0 | AG34: 1692.3833 | AH34: 3648.7587 | AI34: 4098.45 | AJ34: 20308.6 | AK34: 43785.104 | AL34: 49181.4 | AM34: 37758.368 | AN34: 3283.7587 | AO34: 3733.45 | AP34: 39405.104 | AQ34: 44801.4 | AR34: 42103.252
A35: AUS | B35: 36 | C35: 2023
A36: AUT | B36: 40 | C36: 1990 | D36: 275.6057 | E36: 441.5798 | F36: 579.7098 | G36: 3307.2684 | H36: 5298.9576 | I36: 6956.5176 | J36: 5187.5812 | K36: 207.195 | L36: 207.195 | M36: 173.3168 | N36: 173.3168 | O36: 173.3168 | P36: 0 | Q36: 0 | R36: 0 | S36: 0 | T36: 0 | U36: 0 | V36: 2486.34 | W36: 2486.34 | X36: 2079.8016 | Y36: 2079.8016 | Z36: 2079.8016 | AA36: 0 | AB36: 0 | AC36: 0 | AD36: 0 | AE36: 0 | AF36: 0 | AG36: 448.9225 | AH36: 822.0916 | AI36: 960.2216 | AJ36: 5387.07 | AK36: 9865.0992 | AL36: 11522.659 | AM36: 8924.9428 | AN36: 648.7748 | AO36: 786.9048 | AP36: 7785.2976 | AQ36: 9442.8576 | AR36: 8614.0776
A37: AUT | B37: 40 | C37: 1991 | D37: 275.6057 | E37: 441.5798 | F37: 579.7098 | G37: 3307.2684 | H37: 5298.9576 | I37: 6956.5176 | J37: 5187.5812 | K37: 207.195 | L37: 207.195 | M37: 173.3168 | N37: 173.3168 | O37: 173.3168 | P37: 0 | Q37: 0 | R37: 0 | S37: 0 | T37: 0 | U37: 0 | V37: 2486.34 | W37: 2486.34 | X37: 2079.8016 | Y37: 2079.8016 | Z37: 2079.8016 | AA37: 0 | AB37: 0 | AC37: 0 | AD37: 0 | AE37: 0 | AF37: 0 | AG37: 448.9225 | AH37: 822.0916 | AI37: 960.2216 | AJ37: 5387.07 | AK37: 9865.0992 | AL37: 11522.659 | AM37: 8924.9428 | AN37: 648.7748 | AO37: 786.9048 | AP37: 7785.2976 | AQ37: 9442.8576 | AR37: 8614.0776
A38: AUT | B38: 40 | C38: 1992 | D38: 316.245 | E38: 499.449 | F38: 657.935 | G38: 3794.94 | H38: 5993.388 | I38: 7895.22 | J38: 5894.516 | K38: 207.195 | L38: 207.195 | M38: 195.4903 | N38: 195.4903 | O38: 195.4903 | P38: 0 | Q38: 0 | R38: 0 | S38: 0 | T38: 0 | U38: 0 | V38: 2486.34 | W38: 2486.34 | X38: 2345.8836 | Y38: 2345.8836 | Z38: 2345.8836 | AA38: 0 | AB38: 0 | AC38: 0 | AD38: 0 | AE38: 0 | AF38: 0 | AG38: 511.7353 | AH38: 902.1343 | AI38: 1060.6203 | AJ38: 6140.8236 | AK38: 10825.612 | AL38: 12727.444 | AM38: 9897.9596 | AN38: 706.644 | AO38: 865.13 | AP38: 8479.728 | AQ38: 10381.56 | AR38: 9430.644
A39: AUT | B39: 40 | C39: 1993 | D39: 329.331 | E39: 519.078 | F39: 684.107 | G39: 3951.972 | H39: 6228.936 | I39: 8209.284 | J39: 6130.064 | K39: 301.09941 | L39: 301.09941 | M39: 201.9606 | N39: 201.9606 | O39: 201.9606 | P39: 0 | Q39: 0 | R39: 0 | S39: 0 | T39: 0 | U39: 0 | V39: 3613.1929 | W39: 3613.1929 | X39: 2423.5272 | Y39: 2423.5272 | Z39: 2423.5272 | AA39: 0 | AB39: 0 | AC39: 0 | AD39: 0 | AE39: 0 | AF39: 0 | AG39: 531.2916 | AH39: 1022.138 | AI39: 1187.167 | AJ39: 6375.4992 | AK39: 12265.656 | AL39: 14246.004 | AM39: 10962.386 | AN39: 820.17741 | AO39: 985.20641 | AP39: 9842.1289 | AQ39: 11822.477 | AR39: 10832.303
A40: AUT | B40: 40 | C40: 1994 | D40: 337.328 | E40: 539.7248 | F40: 700.2464 | G40: 4047.936 | H40: 6476.6976 | I40: 8402.9568 | J40: 6309.1968 | K40: 301.09941 | L40: 301.09941 | M40: 208.4309 | N40: 208.4309 | O40: 208.4309 | P40: 0 | Q40: 0 | R40: 0 | S40: 0 | T40: 0 | U40: 0 | V40: 3613.1929 | W40: 3613.1929 | X40: 2501.1708 | Y40: 2501.1708 | Z40: 2501.1708 | AA40: 0 | AB40: 0 | AC40: 0 | AD40: 0 | AE40: 0 | AF40: 0 | AG40: 545.7589 | AH40: 1049.2551 | AI40: 1209.7767 | AJ40: 6549.1068 | AK40: 12591.061 | AL40: 14517.321 | AM40: 11219.163 | AN40: 840.82421 | AO40: 1001.3458 | AP40: 10089.891 | AQ40: 12016.15 | AR40: 11053.02
A41: AUT | B41: 40 | C41: 1995 | D41: 346.779 | E41: 554.8464 | F41: 719.8754 | G41: 4161.348 | H41: 6658.1568 | I41: 8638.5048 | J41: 6486.0032 | K41: 301.09941 | L41: 301.09941 | M41: 214.3196 | N41: 214.3196 | O41: 214.3196 | P41: 0 | Q41: 0 | R41: 0 | S41: 0 | T41: 0 | U41: 0 | V41: 3613.1929 | W41: 3613.1929 | X41: 2571.8352 | Y41: 2571.8352 | Z41: 2571.8352 | AA41: 0 | AB41: 0 | AC41: 0 | AD41: 0 | AE41: 0 | AF41: 0 | AG41: 561.0986 | AH41: 1070.2654 | AI41: 1235.2944 | AJ41: 6733.1832 | AK41: 12843.185 | AL41: 14823.533 | AM41: 11466.634 | AN41: 855.94581 | AO41: 1020.9748 | AP41: 10271.35 | AQ41: 12251.698 | AR41: 11261.524
A42: AUT | B42: 40 | C42: 1996 | D42: 354.776 | E42: 567.6416 | F42: 736.451 | G42: 4257.312 | H42: 6811.6992 | I42: 8837.412 | J42: 6635.4744 | K42: 301.09941 | L42: 301.09941 | M42: 225.37 | N42: 227.74511 | O42: 227.74511 | P42: 0 | Q42: 0 | R42: 0 | S42: 0 | T42: 0 | U42: 0 | V42: 3613.1929 | W42: 3613.1929 | X42: 2704.44 | Y42: 2732.9413 | Z42: 2732.9413 | AA42: 0 | AB42: 0 | AC42: 0 | AD42: 0 | AE42: 0 | AF42: 0 | AG42: 580.146 | AH42: 1096.4861 | AI42: 1265.2955 | AJ42: 6961.752 | AK42: 13157.833 | AL42: 15183.546 | AM42: 11767.711 | AN42: 868.74101 | AO42: 1037.5504 | AP42: 10424.892 | AQ42: 12450.605 | AR42: 11437.749
A43: AUT | B43: 40 | C43: 1997 | D43: 354.776 | E43: 567.6416 | F43: 778.4716 | G43: 4257.312 | H43: 6811.6992 | I43: 9341.6592 | J43: 6803.5568 | K43: 301.09941 | L43: 301.09941 | M43: 236.4204 | N43: 241.16989 | O43: 241.16989 | P43: 0 | Q43: 0 | R43: 0 | S43: 0 | T43: 0 | U43: 0 | V43: 3613.1929 | W43: 3613.1929 | X43: 2837.0448 | Y43: 2894.0387 | Z43: 2894.0387 | AA43: 0 | AB43: 0 | AC43: 0 | AD43: 0 | AE43: 0 | AF43: 0 | AG43: 591.1964 | AH43: 1109.9109 | AI43: 1320.7409 | AJ43: 7094.3568 | AK43: 13318.931 | AL43: 15848.891 | AM43: 12087.393 | AN43: 868.74101 | AO43: 1079.571 | AP43: 10424.892 | AQ43: 12954.852 | AR43: 11689.872
A44: AUT | B44: 40 | C44: 1998 | D44: 358.3383 | E44: 573.3122 | F44: 767.9301 | G44: 4300.0596 | H44: 6879.7464 | I44: 9215.1612 | J44: 6798.3224 | K44: 301.09941 | L44: 301.09941 | M44: 247.4708 | N44: 254.5954 | O44: 254.5954 | P44: 0 | Q44: 0 | R44: 0 | S44: 0 | T44: 0 | U44: 0 | V44: 3613.1929 | W44: 3613.1929 | X44: 2969.6496 | Y44: 3055.1448 | Z44: 3055.1448 | AA44: 0 | AB44: 0 | AC44: 0 | AD44: 0 | AE44: 0 | AF44: 0 | AG44: 605.8091 | AH44: 1129.007 | AI44: 1323.6249 | AJ44: 7269.7092 | AK44: 13548.084 | AL44: 15883.499 | AM44: 12233.764 | AN44: 874.41161 | AO44: 1069.0295 | AP44: 10492.939 | AQ44: 12828.354 | AR44: 11660.647
A45: AUT | B45: 40 | C45: 1999 | D45: 364.8813 | E45: 583.7083 | F45: 757.3159 | G45: 4378.5756 | H45: 7004.4996 | I45: 9087.7908 | J45: 6823.622 | K45: 337.44941 | L45: 337.44941 | M45: 258.5212 | N45: 268.02091 | O45: 268.02091 | P45: 0 | Q45: 0 | R45: 0 | S45: 0 | T45: 0 | U45: 0 | V45: 4049.3929 | W45: 4049.3929 | X45: 3102.2544 | Y45: 3216.2509 | Z45: 3216.2509 | AA45: 0 | AB45: 0 | AC45: 0 | AD45: 0 | AE45: 0 | AF45: 0 | AG45: 623.4025 | AH45: 1189.1786 | AI45: 1362.7862 | AJ45: 7480.83 | AK45: 14270.143 | AL45: 16353.435 | AM45: 12701.469 | AN45: 921.15771 | AO45: 1094.7653 | AP45: 11053.893 | AQ45: 13137.184 | AR45: 12095.538
A46: AUT | B46: 40 | C46: 2000 | D46: 373.8234 | E46: 595.413 | F46: 772.4375 | G46: 4485.8808 | H46: 7144.956 | I46: 9269.25 | J46: 6966.6956 | K46: 343.5075 | L46: 343.5075 | M46: 269.5716 | N46: 281.44569 | O46: 281.44569 | P46: 0 | Q46: 0 | R46: 0 | S46: 0 | T46: 0 | U46: 0 | V46: 4122.09 | W46: 4122.09 | X46: 3234.8592 | Y46: 3377.3483 | Z46: 3377.3483 | AA46: 0 | AB46: 0 | AC46: 0 | AD46: 0 | AE46: 0 | AF46: 0 | AG46: 643.395 | AH46: 1220.3662 | AI46: 1397.3907 | AJ46: 7720.74 | AK46: 14644.394 | AL46: 16768.688 | AM46: 13044.608 | AN46: 938.9205 | AO46: 1115.945 | AP46: 11267.046 | AQ46: 13391.34 | AR46: 12329.193
A47: AUT | B47: 40 | C47: 2001 | D47: 379.494 | E47: 607.045 | F47: 787.5591 | G47: 4553.928 | H47: 7284.54 | I47: 9450.7092 | J47: 7096.3924 | K47: 343.5075 | L47: 343.5075 | M47: 280.622 | N47: 294.8712 | O47: 294.8712 | P47: 0 | Q47: 30.291667 | R47: 30.291667 | S47: 0 | T47: 0 | U47: 0 | V47: 4122.09 | W47: 4122.09 | X47: 3367.464 | Y47: 3538.4544 | Z47: 3538.4544 | AA47: 0 | AB47: 363.5 | AC47: 363.5 | AD47: 0 | AE47: 0 | AF47: 0 | AG47: 660.116 | AH47: 1275.7154 | AI47: 1456.2295 | AJ47: 7921.392 | AK47: 15308.584 | AL47: 17474.754 | AM47: 13568.243 | AN47: 980.84417 | AO47: 1161.3583 | AP47: 11770.13 | AQ47: 13936.299 | AR47: 12853.215
... A68: AUT | B68: 40 | C68: 2022 | D68: 758.37505 | E68: 1286.6558 | F68: 1653.8847 | G68: 9100.5006 | H68: 15439.869 | I68: 19846.616 | J68: 14795.662 | K68: 411.22033 | L68: 411.22033 | M68: 365.62829 | N68: 383.34324 | O68: 383.34324 | P68: 0 | Q68: 55.77084 | R68: 55.77084 | S68: 0 | T68: 0 | U68: 0 | V68: 4934.6439 | W68: 4934.6439 | X68: 4387.5395 | Y68: 4600.1189 | Z68: 4600.1189 | AA68: 0 | AB68: 669.25008 | AC68: 669.25008 | AD68: 0 | AE68: 0 | AF68: 0 | AG68: 1124.0033 | AH68: 2136.9902 | AI68: 2504.2191 | AJ68: 13488.04 | AK68: 25643.882 | AL68: 30050.629 | AM68: 23060.85 | AN68: 1753.647 | AO68: 2120.8758 | AP68: 21043.763 | AQ68: 25450.51 | AR68: 23247.137
A69: AUT | B69: 40 | C69: 2023
A70: BEL | B70: 56 | C70: 1990 | D70: 429.1144 | E70: 572.136 | F70: 572.136 | G70: 5149.3728 | H70: 6865.632 | I70: 6865.632 | J70: 6293.5456 | K70: 236.778 | L70: 236.778 | M70: 0 | N70: 0 | O70: 0 | P70: 0 | Q70: 0 | R70: 0 | S70: 0 | T70: 0 | U70: 0 | V70: 2841.336 | W70: 2841.336 | X70: 0 | Y70: 0 | Z70: 0 | AA70: 0 | AB70: 0 | AC70: 0 | AD70: 0 | AE70: 0 | AF70: 0 | AG70: 429.1144 | AH70: 808.914 | AI70: 808.914 | AJ70: 5149.3728 | AK70: 9706.968 | AL70: 9706.968 | AM70: 8187.7696 | AN70: 808.914 | AO70: 808.914 | AP70: 9706.968 | AQ70: 9706.968 | AR70: 9706.968
A71: BEL | B71: 56 | C71: 1991 | D71: 455.3776 | E71: 576.7984 | F71: 576.7984 | G71: 5464.5312 | H71: 6921.5808 | I71: 6921.5808 | J71: 6435.8976 | K71: 256.8846 | L71: 256.8846 | M71: 0 | N71: 0 | O71: 0 | P71: 0 | Q71: 0 | R71: 0 | S71: 0 | T71: 0 | U71: 0 | V71: 3082.6152 | W71: 3082.6152 | X71: 0 | Y71: 0 | Z71: 0 | AA71: 0 | AB71: 0 | AC71: 0 | AD71: 0 | AE71: 0 | AF71: 0 | AG71: 455.3776 | AH71: 833.683 | AI71: 833.683 | AJ71: 5464.5312 | AK71: 10004.196 | AL71: 10004.196 | AM71: 8490.9744 | AN71: 833.683 | AO71: 833.683 | AP71: 10004.196 | AQ71: 10004.196 | AR71: 10004.196
A72: BEL | B72: 56 | C72: 1992 | D72: 464.4792 | E72: 619.2808 | F72: 619.2808 | G72: 5573.7504 | H72: 7431.3696 | I72: 7431.3696 | J72: 6812.1632 | K72: 276.9912 | L72: 276.9912 | M72: 0 | N72: 0 | O72: 0 | P72: 0 | Q72: 0 | R72: 0 | S72: 0 | T72: 0 | U72: 0 | V72: 3323.8944 | W72: 3323.8944 | X72: 0 | Y72: 0 | Z72: 0 | AA72: 0 | AB72: 0 | AC72: 0 | AD72: 0 | AE72: 0 | AF72: 0 | AG72: 464.4792 | AH72: 896.272 | AI72: 896.272 | AJ72: 5573.7504 | AK72: 10755.264 | AL72: 10755.264 | AM72: 9028.0928 | AN72: 896.272 | AO72: 896.272 | AP72: 10755.264 | AQ72: 10755.264 | AR72: 10755.264
A73: BEL | B73: 56 | C73: 1993 | D73: 483.228 | E73: 644.304 | F73: 644.304 | G73: 5798.736 | H73: 7731.648 | I73: 7731.648 | J73: 7087.344 | K73: 283.1168 | L73: 283.1168 | M73: 0 | N73: 0 | O73: 0 | P73: 0 | Q73: 0 | R73: 0 | S73: 0 | T73: 0 | U73: 0 | V73: 3397.4016 | W73: 3397.4016 | X73: 0 | Y73: 0 | Z73: 0 | AA73: 0 | AB73: 0 | AC73: 0 | AD73: 0 | AE73: 0 | AF73: 0 | AG73: 483.228 | AH73: 927.4208 | AI73: 927.4208 | AJ73: 5798.736 | AK73: 11129.05 | AL73: 11129.05 | AM73: 9352.2784 | AN73: 927.4208 | AO73: 927.4208 | AP73: 11129.05 | AQ73: 11129.05 | AR73: 11129.05
A74: BEL | B74: 56 | C74: 1994 | D74: 488.7832 | E74: 651.7192 | F74: 651.7192 | G74: 5865.3984 | H74: 7820.6304 | I74: 7820.6304 | J74: 7168.8864 | K74: 289.2424 | L74: 289.2424 | M74: 0 | N74: 0 | O74: 0 | P74: 0 | Q74: 0 | R74: 0 | S74: 0 | T74: 0 | U74: 0 | V74: 3470.9088 | W74: 3470.9088 | X74: 0 | Y74: 0 | Z74: 0 | AA74: 0 | AB74: 0 | AC74: 0 | AD74: 0 | AE74: 0 | AF74: 0 | AG74: 488.7832 | AH74: 940.9616 | AI74: 940.9616 | AJ74: 5865.3984 | AK74: 11291.539 | AL74: 11291.539 | AM74: 9482.8256 | AN74: 940.9616 | AO74: 940.9616 | AP74: 11291.539 | AQ74: 11291.539 | AR74: 11291.539
A75: BEL | B75: 56 | C75: 1995 | D75: 498.5544 | E75: 664.764 | F75: 664.764 | G75: 5982.6528 | H75: 7977.168 | I75: 7977.168 | J75: 7312.3296 | K75: 295.368 | L75: 295.368 | M75: 0 | N75: 0 | O75: 0 | P75: 0 | Q75: 0 | R75: 0 | S75: 0 | T75: 0 | U75: 0 | V75: 3544.416 | W75: 3544.416 | X75: 0 | Y75: 0 | Z75: 0 | AA75: 0 | AB75: 0 | AC75: 0 | AD75: 0 | AE75: 0 | AF75: 0 | AG75: 498.5544 | AH75: 960.132 | AI75: 960.132 | AJ75: 5982.6528 | AK75: 11521.584 | AL75: 11521.584 | AM75: 9675.2736 | AN75: 960.132 | AO75: 960.132 | AP75: 11521.584 | AQ75: 11521.584 | AR75: 11521.584
A76: BEL | B76: 56 | C76: 1996 | D76: 508.524 | E76: 678.0568 | F76: 678.0568 | G76: 6102.288 | H76: 8136.6816 | I76: 8136.6816 | J76: 7458.5504 | K76: 301.32 | L76: 301.32 | M76: 0 | N76: 0 | O76: 0 | P76: 0 | Q76: 0 | R76: 0 | S76: 0 | T76: 0 | U76: 0 | V76: 3615.84 | W76: 3615.84 | X76: 0 | Y76: 0 | Z76: 0 | AA76: 0 | AB76: 0 | AC76: 0 | AD76: 0 | AE76: 0 | AF76: 0 | AG76: 508.524 | AH76: 979.3768 | AI76: 979.3768 | AJ76: 6102.288 | AK76: 11752.522 | AL76: 11752.522 | AM76: 9869.1104 | AN76: 979.3768 | AO76: 979.3768 | AP76: 11752.522 | AQ76: 11752.522 | AR76: 11752.522
A77: BEL | B77: 56 | C77: 1997 | D77: 508.524 | E77: 678.0568 | F77: 678.0568 | G77: 6102.288 | H77: 8136.6816 | I77: 8136.6816 | J77: 7458.5504 | K77: 307.272 | L77: 307.272 | M77: 0 | N77: 0 | O77: 0 | P77: 0 | Q77: 0 | R77: 0 | S77: 0 | T77: 0 | U77: 0 | V77: 3687.264 | W77: 3687.264 | X77: 0 | Y77: 0 | Z77: 0 | AA77: 0 | AB77: 0 | AC77: 0 | AD77: 0 | AE77: 0 | AF77: 0 | AG77: 508.524 | AH77: 985.3288 | AI77: 985.3288 | AJ77: 6102.288 | AK77: 11823.946 | AL77: 11823.946 | AM77: 9916.7264 | AN77: 985.3288 | AO77: 985.3288 | AP77: 11823.946 | AQ77: 11823.946 | AR77: 11823.946
A78: BEL | B78: 56 | C78: 1998 | D78: 518.7168 | E78: 691.6224 | F78: 691.6224 | G78: 6224.6016 | H78: 8299.4688 | I78: 8299.4688 | J78: 7607.8464 | K78: 304.42 | L78: 304.42 | M78: 0 | N78: 0 | O78: 0 | P78: 0 | Q78: 0 | R78: 0 | S78: 0 | T78: 0 | U78: 0 | V78: 3653.04 | W78: 3653.04 | X78: 0 | Y78: 0 | Z78: 0 | AA78: 0 | AB78: 0 | AC78: 0 | AD78: 0 | AE78: 0 | AF78: 0 | AG78: 518.7168 | AH78: 996.0424 | AI78: 996.0424 | AJ78: 6224.6016 | AK78: 11952.509 | AL78: 11952.509 | AM78: 10043.206 | AN78: 996.0424 | AO78: 996.0424 | AP78: 11952.509 | AQ78: 11952.509 | AR78: 11952.509
A79: BEL | B79: 56 | C79: 1999 | D79: 524.1232 | E79: 705.436 | F79: 705.436 | G79: 6289.4784 | H79: 8465.232 | I79: 8465.232 | J79: 7739.9808 | K79: 301.568 | L79: 301.568 | M79: 0 | N79: 0 | O79: 0 | P79: 0 | Q79: 0 | R79: 0 | S79: 0 | T79: 0 | U79: 0 | V79: 3618.816 | W79: 3618.816 | X79: 0 | Y79: 0 | Z79: 0 | AA79: 0 | AB79: 0 | AC79: 0 | AD79: 0 | AE79: 0 | AF79: 0 | AG79: 524.1232 | AH79: 1007.004 | AI79: 1007.004 | AJ79: 6289.4784 | AK79: 12084.048 | AL79: 12084.048 | AM79: 10152.525 | AN79: 1007.004 | AO79: 1007.004 | AP79: 12084.048 | AQ79: 12084.048 | AR79: 12084.048
A80: BEL | B80: 56 | C80: 2000 | D80: 539.6728 | E80: 719.572 | F80: 719.572 | G80: 6476.0736 | H80: 8634.864 | I80: 8634.864 | J80: 7915.2672 | K80: 312.9264 | L80: 312.9264 | M80: 0 | N80: 0 | O80: 0 | P80: 0 | Q80: 0 | R80: 0 | S80: 0 | T80: 0 | U80: 0 | V80: 3755.1168 | W80: 3755.1168 | X80: 0 | Y80: 0 | Z80: 0 | AA80: 0 | AB80: 0 | AC80: 0 | AD80: 0 | AE80: 0 | AF80: 0 | AG80: 539.6728 | AH80: 1032.4984 | AI80: 1032.4984 | AJ80: 6476.0736 | AK80: 12389.981 | AL80: 12389.981 | AM80: 10418.678 | AN80: 1032.4984 | AO80: 1032.4984 | AP80: 12389.981 | AQ80: 12389.981 | AR80: 12389.981
...

Sheet SaMip 3.0_PPPs
A1: Country | B1: Country.nr | C1: Year | D1: PPPs* | E1: SAsi | F1: SAlp | G1: SAfa | H1: SAsiy | I1: SAlpy | J1: SAfay | K1: SAavey | L1: CSUPPlp | M1: CSUPPfa | N1: HSUPPsi | O1: HSUPPlp | P1: HSUPPfa | Q1: TCREDsi | R1: TCREDlp | S1: TCREDfa | T1: OTHsi | U1: OTHlp | V1: OTHfa | W1: CSUPPlpy | X1: CSUPPfay | Y1: HSUPPsiy | Z1: HSUPPlpy | AA1: HSUPPfay | AB1: TCREDsiy | AC1: TCREDlpy | AD1: TCREDfay | AE1: OTHsiy | AF1: OTHlpy | AG1: OTHfay | AH1: MIPsi | AI1: MIPlp | AJ1: MIPfa | AK1: MIPsiy | AL1: MIPlpy | AM1: MIPfay | AN1: MIPavey | AO1: FAlp | AP1: FAfa | AQ1: FAlpy | AR1: FAfay | AS1: FAavey
A2: AUS | B2: 36 | C2: 1990 | D2: 1.364415 | E2: 396.20155 | F2: 448.44616 | G2: 707.28725 | H2: 4754.4186 | I2: 5381.3539 | J2: 8487.447 | K2: 6207.7398 | L2: 247.72522 | M2: 247.72522 | N2: 79.399108 | O2: 95.278929 | P2: 95.278929 | Q2: 0 | R2: 0 | S2: 0 | T2: 0 | U2: 0 | V2: 0 | W2: 2972.7026 | X2: 2972.7026 | Y2: 952.78929 | Z2: 1143.3471 | AA2: 1143.3471 | AB2: 0 | AC2: 0 | AD2: 0 | AE2: 0 | AF2: 0 | AG2: 0 | AH2: 475.60065 | AI2: 791.4503 | AJ2: 1050.2914 | AK2: 5707.2079 | AL2: 9497.4036 | AM2: 12603.497 | AN2: 9269.3694 | AO2: 696.17138 | AP2: 955.01247 | AQ2: 8354.0565 | AR2: 11460.15 | AS2: 9907.103
A3: AUS | B3: 36 | C3: 1991 | D3: 1.347277 | E3: 431.95769 | F3: 469.1067 | G3: 782.21974 | H3: 5183.4923 | I3: 5629.2804 | J3: 9386.6369 | K3: 6733.1365 | L3: 273.88577 | M3: 273.88577 | N3: 99.707286 | O3: 116.43238 | P3: 116.43238 | Q3: 0 | R3: 0 | S3: 0 | T3: 0 | U3: 0 | V3: 0 | W3: 3286.6293 | X3: 3286.6293 | Y3: 1196.4874 | Z3: 1397.1886 | AA3: 1397.1886 | AB3: 0 | AC3: 0 | AD3: 0 | AE3: 0 | AF3: 0 | AG3: 0 | AH3: 531.66498 | AI3: 859.42485 | AJ3: 1172.5379 | AK3: 6379.9798 | AL3: 10313.098 | AM3: 14070.455 | AN3: 10254.511 | AO3: 742.99247 | AP3: 1056.1055 | AQ3: 8915.9096 | AR3: 12673.266 | AS3: 10794.588
A4: AUS | B4: 36 | C4: 1992 | D4: 1.32667 | E4: 453.52901 | F4: 492.56158 | G4: 821.48035 | H4: 5442.3481 | I4: 5910.7389 | J4: 9857.7642 | K4: 7070.2837 | L4: 287.59978 | M4: 287.59978 | N4: 102.72587 | O4: 120.03739 | P4: 120.03739 | Q4: 0 | R4: 0 | S4: 0 | T4: 0 | U4: 0 | V4: 0 | W4: 3451.1974 | X4: 3451.1974 | Y4: 1232.7105 | Z4: 1440.4486 | AA4: 1440.4486 | AB4: 0 | AC4: 0 | AD4: 0 | AE4: 0 | AF4: 0 | AG4: 0 | AH4: 556.25488 | AI4: 900.19874 | AJ4: 1229.1175 | AK4: 6675.0586 | AL4: 10802.385 | AM4: 14749.41 | AN4: 10742.285 | AO4: 780.16136 | AP4: 1109.0801 | AQ4: 9361.9363 | AR4: 13308.962 | AS4: 11335.449
A5: AUS | B5: 36 | C5: 1993 | D5: 1.31089 | E5: 465.93027 | F5: 515.84801 | G5: 843.93046 | H5: 5591.1633 | I5: 6190.1761 | J5: 10127.166 | K5: 7302.835 | L5: 315.85411 | M5: 315.85411 | N5: 111.06958 | O5: 129.74646 | P5: 129.74646 | Q5: 0 | R5: 0 | S5: 0 | T5: 0 | U5: 0 | V5: 0 | W5: 3790.2494 | X5: 3790.2494 | Y5: 1332.8349 | Z5: 1556.9575 | AA5: 1556.9575 | AB5: 0 | AC5: 0 | AD5: 0 | AE5: 0 | AF5: 0 | AG5: 0 | AH5: 576.99985 | AI5: 961.44858 | AJ5: 1289.531 | AK5: 6923.9982 | AL5: 11537.383 | AM5: 15474.372 | AN5: 11311.918 | AO5: 831.70213 | AP5: 1159.7846 | AQ5: 9980.4255 | AR5: 13917.415 | AS5: 11948.92
A6: AUS | B6: 36 | C6: 1994 | D6: 1.299225 | E6: 477.61807 | F6: 530.48548 | G6: 879.52433 | H6: 5731.4168 | I6: 6365.8258 | J6: 10554.292 | K6: 7550.5115 | L6: 329.19625 | M6: 329.19625 | N6: 114.068 | O6: 133.27946 | P6: 133.27946 | Q6: 0 | R6: 0 | S6: 0 | T6: 0 | U6: 0 | V6: 0 | W6: 3950.355 | X6: 3950.355 | Y6: 1368.816 | Z6: 1599.3535 | AA6: 1599.3535 | AB6: 0 | AC6: 0 | AD6: 0 | AE6: 0 | AF6: 0 | AG6: 0 | AH6: 591.68607 | AI6: 992.96119 | AJ6: 1342 | AK6: 7100.2328 | AL6: 11915.534 | AM6: 16104 | AN6: 11706.589 | AO6: 859.68173 | AP6: 1208.7206 | AQ6: 10316.181 | AR6: 14504.647 | AS6: 12410.414
A7: AUS | B7: 36 | C7: 1995 | D7: 1.308996 | E7: 492.0947 | F7: 564.63121 | G7: 887.19395 | H7: 5905.1365 | I7: 6775.5746 | J7: 10646.327 | K7: 7775.6795 | L7: 338.81693 | M7: 338.81693 | N7: 116.19592 | O7: 135.72743 | P7: 135.72743 | Q7: 0 | R7: 0 | S7: 0 | T7: 0 | U7: 0 | V7: 0 | W7: 4065.8031 | X7: 4065.8031 | Y7: 1394.3511 | Z7: 1628.7292 | AA7: 1628.7292 | AB7: 0 | AC7: 0 | AD7: 0 | AE7: 0 | AF7: 0 | AG7: 0 | AH7: 608.29063 | AI7: 1039.1756 | AJ7: 1361.7383 | AK7: 7299.4875 | AL7: 12470.107 | AM7: 16340.86 | AN7: 12036.818 | AO7: 903.44814 | AP7: 1226.0109 | AQ7: 10841.378 | AR7: 14712.131 | AS7: 12776.754
A8: AUS | B8: 36 | C8: 1996 | D8: 1.311426 | E8: 512.9912 | F8: 608.84106 | G8: 925.20152 | H8: 6155.8944 | I8: 7306.0928 | J8: 11102.418 | K8: 8188.1352 | L8: 354.15647 | M8: 354.15647 | N8: 121.92834 | O8: 133.72466 | P8: 133.72466 | Q8: 0 | R8: 0 | S8: 0 | T8: 0 | U8: 0 | V8: 0 | W8: 4249.8776 | X8: 4249.8776 | Y8: 1463.1401 | Z8: 1604.696 | AA8: 1604.696 | AB8: 0 | AC8: 0 | AD8: 0 | AE8: 0 | AF8: 0 | AG8: 0 | AH8: 634.91955 | AI8: 1096.7222 | AJ8: 1413.0827 | AK8: 7619.0345 | AL8: 13160.666 | AM8: 16956.992 | AN8: 12578.898 | AO8: 962.99753 | AP8: 1279.358 | AQ8: 11555.97 | AR8: 15352.296 | AS8: 13454.133
A9: AUS | B9: 36 | C9: 1997 | D9: 1.306627 | E9: 530.96 | F9: 585.70656 | G9: 955.13104 | H9: 6371.52 | I9: 7028.4787 | J9: 11461.572 | K9: 8287.1904 | L9: 469.45303 | M9: 469.45303 | N9: 124.03438 | O9: 144.92787 | P9: 144.92787 | Q9: 0 | R9: 0 | S9: 0 | T9: 0 | U9: 0 | V9: 0 | W9: 5633.4363 | X9: 5633.4363 | Y9: 1488.4125 | Z9: 1739.1344 | AA9: 1739.1344 | AB9: 0 | AC9: 0 | AD9: 0 | AE9: 0 | AF9: 0 | AG9: 0 | AH9: 654.99437 | AI9: 1200.0875 | AJ9: 1569.5119 | AK9: 7859.9325 | AL9: 14401.049 | AM9: 18834.143 | AN9: 13698.375 | AO9: 1055.1596 | AP9: 1424.5841 | AQ9: 12661.915 | AR9: 17095.009 | AS9: 14878.462
A10: AUS | B10: 36 | C10: 1998 | D10: 1.298972 | E10: 536.25739 | F10: 614.67838 | G10: 967.43168 | H10: 6435.0887 | I10: 7376.1405 | J10: 11609.18 | K10: 8473.4698 | L10: 478.45527 | M10: 478.45527 | N10: 125.43252 | O10: 146.58258 | P10: 146.58258 | Q10: 0 | R10: 0 | S10: 0 | T10: 0 | U10: 0 | V10: 0 | W10: 5741.4632 | X10: 5741.4632 | Y10: 1505.1903 | Z10: 1758.991 | AA10: 1758.991 | AB10: 0 | AC10: 0 | AD10: 0 | AE10: 0 | AF10: 0 | AG10: 0 | AH10: 661.68991 | AI10: 1239.7162 | AJ10: 1592.4695 | AK10: 7940.2789 | AL10: 14876.595 | AM10: 19109.634 | AN10: 13975.503 | AO10: 1093.1336 | AP10: 1445.887 | AQ10: 13117.604 | AR10: 17350.643 | AS10: 15234.124
A11: AUS | B11: 36 | C11: 1999 | D11: 1.29695 | E11: 540.26755 | F11: 621.30383 | G11: 974.95406 | H11: 6483.2106 | I11: 7455.6459 | J11: 11699.449 | K11: 8546.1018 | L11: 485.44662 | M11: 485.44662 | N11: 126.63043 | O11: 147.98052 | P11: 147.98052 | Q11: 0 | R11: 0 | S11: 0 | T11: 0 | U11: 0 | V11: 0 | W11: 5825.3595 | X11: 5825.3595 | Y11: 1519.5651 | Z11: 1775.7662 | AA11: 1775.7662 | AB11: 0 | AC11: 0 | AD11: 0 | AE11: 0 | AF11: 0 | AG11: 0 | AH11: 666.89798 | AI11: 1254.731 | AJ11: 1608.3812 | AK11: 8002.7757 | AL11: 15056.772 | AM11: 19300.574 | AN11: 14120.041 | AO11: 1106.7505 | AP11: 1460.4007 | AQ11: 13281.005 | AR11: 17524.808 | AS11: 15402.907
A12: AUS | B12: 36 | C12: 2000 | D12: 1.31208 | E12: 539.48692 | F12: 608.53759 | G12: 973.28923 | H12: 6473.8431 | I12: 7302.4511 | J12: 11679.471 | K12: 8485.255 | L12: 597.02914 | M12: 597.02914 | N12: 140.71551 | O12: 164.35736 | P12: 164.35736 | Q12: 0 | R12: 0 | S12: 0 | T12: 0 | U12: 0 | V12: 0 | W12: 7164.3497 | X12: 7164.3497 | Y12: 1688.5861 | Z12: 1972.2883 | AA12: 1972.2883 | AB12: 0 | AC12: 0 | AD12: 0 | AE12: 0 | AF12: 0 | AG12: 0 | AH12: 680.20243 | AI12: 1369.9241 | AJ12: 1734.6757 | AK12: 8162.4291 | AL12: 16439.089 | AM12: 20816.109 | AN12: 15139.209 | AO12: 1205.5667 | AP12: 1570.3184 | AQ12: 14466.801 | AR12: 18843.82 | AS12: 16655.311
A13: AUS | B13: 36 | C13: 2001 | D13: 1.327545 | E13: 572.53552 | F13: 665.58949 | G13: 1032.7836 | H13: 6870.4262 | I13: 7987.0739 | J13: 12393.403 | K13: 9083.6343 | L13: 705.88944 | M13: 705.88944 | N13: 143.62351 | O13: 167.74573 | P13: 167.74573 | Q13: 0 | R13: 0 | S13: 0 | T13: 0 | U13: 0 | V13: 0 | W13: 8470.6733 | X13: 8470.6733 | Y13: 1723.4821 | Z13: 2012.9487 | AA13: 2012.9487 | AB13: 0 | AC13: 0 | AD13: 0 | AE13: 0 | AF13: 0 | AG13: 0 | AH13: 716.15903 | AI13: 1539.2247 | AJ13: 1906.4187 | AK13: 8593.9083 | AL13: 18470.696 | AM13: 22877.025 | AN13: 16647.21 | AO13: 1371.4789 | AP13: 1738.673 | AQ13: 16457.747 | AR13: 20864.076 | AS13: 18660.912
... A34: AUS | B34: 36 | C34: 2022 | D34: 1.371019 | E34: 1008.7266 | F34: 1135.6273 | G34: 1836.9792 | H34: 12104.719 | I34: 13627.528 | J34: 22043.75 | K34: 15925.332 | L34: 1259.4953 | M34: 886.14138 | N34: 225.67156 | O34: 266.22534 | P34: 266.22534 | Q34: 0 | R34: 0 | S34: 0 | T34: 0 | U34: 0 | V34: 0 | W34: 15113.944 | X34: 10633.697 | Y34: 2708.0588 | Z34: 3194.7041 | AA34: 3194.7041 | AB34: 0 | AC34: 0 | AD34: 0 | AE34: 0 | AF34: 0 | AG34: 0 | AH34: 1234.3982 | AI34: 2661.348 | AJ34: 2989.3459 | AK34: 14812.778 | AL34: 31936.176 | AM34: 35872.151 | AN34: 27540.368 | AO34: 2395.1227 | AP34: 2723.1205 | AQ34: 28741.472 | AR34: 32677.446 | AS34: 30709.459
A35: AUS | B35: 36 | C35: 2023
A36: AUT | B36: 40 | C36: 1990 | D36: 0.920645 | E36: 299.36153 | F36: 479.64177 | G36: 629.67789 | H36: 3592.3384 | I36: 5755.7013 | J36: 7556.1347 | K36: 5634.7248 | L36: 225.05417 | M36: 225.05417 | N36: 188.25584 | O36: 188.25584 | P36: 188.25584 | Q36: 0 | R36: 0 | S36: 0 | T36: 0 | U36: 0 | V36: 0 | W36: 2700.6501 | X36: 2700.6501 | Y36: 2259.0701 | Z36: 2259.0701 | AA36: 2259.0701 | AB36: 0 | AC36: 0 | AD36: 0 | AE36: 0 | AF36: 0 | AG36: 0 | AH36: 487.61738 | AI36: 892.95179 | AJ36: 1042.9879 | AK36: 5851.4085 | AL36: 10715.421 | AM36: 12515.855 | AN36: 9694.2283 | AO36: 704.69595 | AP36: 854.73206 | AQ36: 8456.3514 | AR36: 10256.785 | AS36: 9356.5681
A37: AUT | B37: 40 | C37: 1991 | D37: 0.922961 | E37: 298.61034 | F37: 478.4382 | G37: 628.09783 | H37: 3583.3241 | I37: 5741.2584 | J37: 7537.1739 | K37: 5620.5855 | L37: 224.48944 | M37: 224.48944 | N37: 187.78345 | O37: 187.78345 | P37: 187.78345 | Q37: 0 | R37: 0 | S37: 0 | T37: 0 | U37: 0 | V37: 0 | W37: 2693.8733 | X37: 2693.8733 | Y37: 2253.4014 | Z37: 2253.4014 | AA37: 2253.4014 | AB37: 0 | AC37: 0 | AD37: 0 | AE37: 0 | AF37: 0 | AG37: 0 | AH37: 486.39379 | AI37: 890.71109 | AJ37: 1040.3707 | AK37: 5836.7255 | AL37: 10688.533 | AM37: 12484.449 | AN37: 9669.9024 | AO37: 702.92764 | AP37: 852.58727 | AQ37: 8435.1317 | AR37: 10231.047 | AS37: 9333.0895
A38: AUT | B38: 40 | C38: 1992 | D38: 0.933791 | E38: 338.66786 | F38: 534.86166 | G38: 704.58486 | H38: 4064.0143 | I38: 6418.3399 | J38: 8455.0183 | K38: 6312.4575 | L38: 221.88584 | M38: 221.88584 | N38: 209.35124 | O38: 209.35124 | P38: 209.35124 | Q38: 0 | R38: 0 | S38: 0 | T38: 0 | U38: 0 | V38: 0 | W38: 2662.6301 | X38: 2662.6301 | Y38: 2512.2148 | Z38: 2512.2148 | AA38: 2512.2148 | AB38: 0 | AC38: 0 | AD38: 0 | AE38: 0 | AF38: 0 | AG38: 0 | AH38: 548.0191 | AI38: 966.09873 | AJ38: 1135.8219 | AK38: 6576.2292 | AL38: 11593.185 | AM38: 13629.863 | AN38: 10599.759 | AO38: 756.74749 | AP38: 926.4707 | AQ38: 9080.9699 | AR38: 11117.648 | AS38: 10099.309
A39: AUT | B39: 40 | C39: 1993 | D39: 0.937319 | E39: 351.35423 | F39: 553.79012 | G39: 729.85504 | H39: 4216.2508 | I39: 6645.4814 | J39: 8758.2605 | K39: 6539.9976 | L39: 321.23472 | M39: 321.23472 | N39: 215.46624 | O39: 215.46624 | P39: 215.46624 | Q39: 0 | R39: 0 | S39: 0 | T39: 0 | U39: 0 | V39: 0 | W39: 3854.8167 | X39: 3854.8167 | Y39: 2585.5949 | Z39: 2585.5949 | AA39: 2585.5949 | AB39: 0 | AC39: 0 | AD39: 0 | AE39: 0 | AF39: 0 | AG39: 0 | AH39: 566.82047 | AI39: 1090.4911 | AJ39: 1266.556 | AK39: 6801.8457 | AL39: 13085.893 | AM39: 15198.672 | AN39: 11695.47 | AO39: 875.02484 | AP39: 1051.0898 | AQ39: 10500.298 | AR39: 12613.077 | AS39: 11556.688
A40: AUT | B40: 40 | C40: 1994 | D40: 0.940894 | E40: 358.5186 | F40: 573.62976 | G40: 744.23516 | H40: 4302.2232 | I40: 6883.5571 | J40: 8930.822 | K40: 6705.5341 | L40: 320.01417 | M40: 320.01417 | N40: 221.52432 | O40: 221.52432 | P40: 221.52432 | Q40: 0 | R40: 0 | S40: 0 | T40: 0 | U40: 0 | V40: 0 | W40: 3840.17 | X40: 3840.17 | Y40: 2658.2918 | Z40: 2658.2918 | AA40: 2658.2918 | AB40: 0 | AC40: 0 | AD40: 0 | AE40: 0 | AF40: 0 | AG40: 0 | AH40: 580.04292 | AI40: 1115.1682 | AJ40: 1285.7736 | AK40: 6960.515 | AL40: 13382.019 | AM40: 15429.284 | AN40: 11923.939 | AO40: 893.64393 | AP40: 1064.2493 | AQ40: 10723.727 | AR40: 12770.992 | AS40: 11747.36
A41: AUT | B41: 40 | C41: 1995 | D41: 0.938286 | E41: 369.58774 | F41: 591.34038 | G41: 767.22385 | H41: 4435.0529 | I41: 7096.0846 | J41: 9206.6862 | K41: 6912.6079 | L41: 320.90366 | M41: 320.90366 | N41: 228.41607 | O41: 228.41607 | P41: 228.41607 | Q41: 0 | R41: 0 | S41: 0 | T41: 0 | U41: 0 | V41: 0 | W41: 3850.8439 | X41: 3850.8439 | Y41: 2740.9928 | Z41: 2740.9928 | AA41: 2740.9928 | AB41: 0 | AC41: 0 | AD41: 0 | AE41: 0 | AF41: 0 | AG41: 0 | AH41: 598.00381 | AI41: 1140.6601 | AJ41: 1316.5436 | AK41: 7176.0457 | AL41: 13687.921 | AM41: 15798.523 | AN41: 12220.83 | AO41: 912.24404 | AP41: 1088.1275 | AQ41: 10946.928 | AR41: 13057.53 | AS41: 12002.229
A42: AUT | B42: 40 | C42: 1996 | D42: 0.934143 | E42: 379.78768 | F42: 607.66028 | G42: 788.37073 | H42: 4557.4521 | I42: 7291.9234 | J42: 9460.4488 | K42: 7103.2748 | L42: 322.32689 | M42: 322.32689 | N42: 241.25857 | O42: 243.80112 | P42: 243.80112 | Q42: 0 | R42: 0 | S42: 0 | T42: 0 | U42: 0 | V42: 0 | W42: 3867.9227 | X42: 3867.9227 | Y42: 2895.1028 | Z42: 2925.6134 | AA42: 2925.6134 | AB42: 0 | AC42: 0 | AD42: 0 | AE42: 0 | AF42: 0 | AG42: 0 | AH42: 621.04624 | AI42: 1173.7883 | AJ42: 1354.4987 | AK42: 7452.5549 | AL42: 14085.46 | AM42: 16253.985 | AN42: 12597.333 | AO42: 929.98717 | AP42: 1110.6976 | AQ42: 11159.846 | AR42: 13328.371 | AS42: 12244.109
A43: AUT | B43: 40 | C43: 1997 | D43: 0.931676 | E43: 380.79332 | F43: 609.26932 | G43: 835.56043 | H43: 4569.5199 | I43: 7311.2318 | J43: 10026.725 | K43: 7302.4923 | L43: 323.18039 | M43: 323.18039 | N43: 253.75817 | O43: 258.85597 | P43: 258.85597 | Q43: 0 | R43: 0 | S43: 0 | T43: 0 | U43: 0 | V43: 0 | W43: 3878.1646 | X43: 3878.1646 | Y43: 3045.0981 | Z43: 3106.2716 | AA43: 3106.2716 | AB43: 0 | AC43: 0 | AD43: 0 | AE43: 0 | AF43: 0 | AG43: 0 | AH43: 634.5515 | AI43: 1191.3057 | AJ43: 1417.5968 | AK43: 7614.618 | AL43: 14295.668 | AM43: 17011.161 | AN43: 12973.816 | AO43: 932.4497 | AP43: 1158.7408 | AQ43: 11189.396 | AR43: 13904.89 | AS43: 12547.143
A44: AUT | B44: 40 | C44: 1998 | D44: 0.92277 | E44: 388.32894 | F44: 621.2948 | G44: 832.20098 | H44: 4659.9473 | I44: 7455.5376 | J44: 9986.4118 | K44: 7367.2989 | L44: 326.29952 | M44: 326.29952 | N44: 268.18254 | O44: 275.90342 | P44: 275.90342 | Q44: 0 | R44: 0 | S44: 0 | T44: 0 | U44: 0 | V44: 0 | W44: 3915.5943 | X44: 3915.5943 | Y44: 3218.1904 | Z44: 3310.8411 | AA44: 3310.8411 | AB44: 0 | AC44: 0 | AD44: 0 | AE44: 0 | AF44: 0 | AG44: 0 | AH44: 656.51148 | AI44: 1223.4977 | AJ44: 1434.4039 | AK44: 7878.1378 | AL44: 14681.973 | AM44: 17212.847 | AN44: 13257.653 | AO44: 947.59432 | AP44: 1158.5005 | AQ44: 11371.132 | AR44: 13902.006 | AS44: 12636.569
A45: AUT | B45: 40 | C45: 1999 | D45: 0.923906 | E45: 394.93336 | F45: 631.78321 | G45: 819.68934 | H45: 4739.2003 | I45: 7581.3985 | J45: 9836.2721 | K45: 7385.6236 | L45: 365.24214 | M45: 365.24214 | N45: 279.81331 | O45: 290.09543 | P45: 290.09543 | Q45: 0 | R45: 0 | S45: 0 | T45: 0 | U45: 0 | V45: 0 | W45: 4382.9057 | X45: 4382.9057 | Y45: 3357.7598 | Z45: 3481.1452 | AA45: 3481.1452 | AB45: 0 | AC45: 0 | AD45: 0 | AE45: 0 | AF45: 0 | AG45: 0 | AH45: 674.74667 | AI45: 1287.1208 | AJ45: 1475.0269 | AK45: 8096.9601 | AL45: 15445.449 | AM45: 17700.323 | AN45: 13747.578 | AO45: 997.02536 | AP45: 1184.9315 | AQ45: 11964.304 | AR45: 14219.178 | AS45: 13091.741
